2023-04-29 23:18:40,768 | ERROR | listdir: path should be string, bytes, os.PathLike or None, not dict
Traceback (most recent call last):
  File "D:\Background\conda\envs\li_env\lib\site-packages\flask\app.py", line 1823, in full_dispatch_request
    rv = self.dispatch_request()
  File "D:\Background\conda\envs\li_env\lib\site-packages\flask\app.py", line 1799, in dispatch_request
    return self.ensure_sync(self.view_functions[rule.endpoint])(**view_args)
  File "D:\Project\Money\flaskTemplate\blueprints\fileController.py", line 12, in get_origin_list
    data = dfs_files(DATA_ADDR)
  File "D:\Project\Money\flaskTemplate\utils\file_utils.py", line 13, in dfs_files
    for item in os.listdir(current_path):
TypeError: listdir: path should be string, bytes, os.PathLike or None, not dict
2023-04-29 23:21:12,994 | ERROR | Object of type resDTO is not JSON serializable
Traceback (most recent call last):
  File "D:\Background\conda\envs\li_env\lib\site-packages\flask\app.py", line 1823, in full_dispatch_request
    rv = self.dispatch_request()
  File "D:\Background\conda\envs\li_env\lib\site-packages\flask\app.py", line 1799, in dispatch_request
    return self.ensure_sync(self.view_functions[rule.endpoint])(**view_args)
  File "D:\Project\Money\flaskTemplate\blueprints\fileController.py", line 13, in get_origin_list
    return jsonify(resDTO(200, "请求成功", [2,3,4]))
  File "D:\Background\conda\envs\li_env\lib\site-packages\flask\json\__init__.py", line 342, in jsonify
    return current_app.json.response(*args, **kwargs)
  File "D:\Background\conda\envs\li_env\lib\site-packages\flask\json\provider.py", line 309, in response
    f"{self.dumps(obj, **dump_args)}\n", mimetype=mimetype
  File "D:\Background\conda\envs\li_env\lib\site-packages\flask\json\provider.py", line 230, in dumps
    return json.dumps(obj, **kwargs)
  File "D:\Background\conda\envs\li_env\lib\json\__init__.py", line 238, in dumps
    **kw).encode(obj)
  File "D:\Background\conda\envs\li_env\lib\json\encoder.py", line 201, in encode
    chunks = list(chunks)
  File "D:\Background\conda\envs\li_env\lib\json\encoder.py", line 438, in _iterencode
    o = _default(o)
  File "D:\Background\conda\envs\li_env\lib\site-packages\flask\json\provider.py", line 122, in _default
    raise TypeError(f"Object of type {type(o).__name__} is not JSON serializable")
TypeError: Object of type resDTO is not JSON serializable
2023-04-29 23:28:55,138 | ERROR | listdir: path should be string, bytes, os.PathLike or None, not dict
Traceback (most recent call last):
  File "D:\Background\conda\envs\li_env\lib\site-packages\flask\app.py", line 1823, in full_dispatch_request
    rv = self.dispatch_request()
  File "D:\Background\conda\envs\li_env\lib\site-packages\flask\app.py", line 1799, in dispatch_request
    return self.ensure_sync(self.view_functions[rule.endpoint])(**view_args)
  File "D:\Project\Money\flaskTemplate\blueprints\fileController.py", line 12, in get_origin_list
    data = dfs_files(DATA_ADDR)
  File "D:\Project\Money\flaskTemplate\utils\file_utils.py", line 13, in dfs_files
    for item in os.listdir(current_path):
TypeError: listdir: path should be string, bytes, os.PathLike or None, not dict
2023-04-29 23:30:21,949 | ERROR | listdir: path should be string, bytes, os.PathLike or None, not dict
Traceback (most recent call last):
  File "D:\Background\conda\envs\li_env\lib\site-packages\flask\app.py", line 1823, in full_dispatch_request
    rv = self.dispatch_request()
  File "D:\Background\conda\envs\li_env\lib\site-packages\flask\app.py", line 1799, in dispatch_request
    return self.ensure_sync(self.view_functions[rule.endpoint])(**view_args)
  File "D:\Project\Money\flaskTemplate\blueprints\fileController.py", line 12, in get_origin_list
    data = dfs_files(DATA_ADDR)
  File "D:\Project\Money\flaskTemplate\utils\file_utils.py", line 13, in dfs_files
    s = os.listdir(current_path)
TypeError: listdir: path should be string, bytes, os.PathLike or None, not dict
2023-04-30 17:49:57,865 | ERROR | 500 Internal Server Error: The server encountered an internal error and was unable to complete your request. Either the server is overloaded or there is an error in the application.
Traceback (most recent call last):
  File "D:\Background\conda\envs\flask365\lib\site-packages\flask\app.py", line 2073, in wsgi_app
    response = self.full_dispatch_request()
  File "D:\Background\conda\envs\flask365\lib\site-packages\flask\app.py", line 1519, in full_dispatch_request
    return self.finalize_request(rv)
  File "D:\Background\conda\envs\flask365\lib\site-packages\flask\app.py", line 1538, in finalize_request
    response = self.make_response(rv)
  File "D:\Background\conda\envs\flask365\lib\site-packages\flask\app.py", line 1716, in make_response
    rv = jsonify(rv)
  File "D:\Background\conda\envs\flask365\lib\site-packages\flask\json\__init__.py", line 361, in jsonify
    f"{dumps(data, indent=indent, separators=separators)}\n",
  File "D:\Background\conda\envs\flask365\lib\site-packages\flask\json\__init__.py", line 139, in dumps
    rv = _json.dumps(obj, **kwargs)
  File "D:\Background\conda\envs\flask365\lib\json\__init__.py", line 238, in dumps
    **kw).encode(obj)
  File "D:\Background\conda\envs\flask365\lib\json\encoder.py", line 199, in encode
    chunks = self.iterencode(o, _one_shot=True)
  File "D:\Background\conda\envs\flask365\lib\json\encoder.py", line 257, in iterencode
    return _iterencode(o, 0)
  File "D:\Background\conda\envs\flask365\lib\site-packages\flask\json\__init__.py", line 57, in default
    return super().default(o)
  File "D:\Background\conda\envs\flask365\lib\json\encoder.py", line 180, in default
    o.__class__.__name__)
TypeError: Object of type 'Record' is not JSON serializable
2023-04-30 17:54:05,856 | ERROR | 'Record' object has no attribute 'uuid'
Traceback (most recent call last):
  File "D:\Background\conda\envs\flask365\lib\site-packages\flask\app.py", line 1516, in full_dispatch_request
    rv = self.dispatch_request()
  File "D:\Background\conda\envs\flask365\lib\site-packages\flask\app.py", line 1502, in dispatch_request
    return self.ensure_sync(self.view_functions[rule.endpoint])(**req.view_args)
  File "D:\Project\Money\flaskTemplate\blueprints\fileController.py", line 43, in get_progress
    "uuid": item.uuid,
AttributeError: 'Record' object has no attribute 'uuid'
2023-04-30 18:06:39,967 | ERROR | 'NoneType' object has no attribute 'ids'
Traceback (most recent call last):
  File "D:\Background\conda\envs\flask365\lib\site-packages\flask\app.py", line 1516, in full_dispatch_request
    rv = self.dispatch_request()
  File "D:\Background\conda\envs\flask365\lib\site-packages\flask\app.py", line 1502, in dispatch_request
    return self.ensure_sync(self.view_functions[rule.endpoint])(**req.view_args)
  File "D:\Project\Money\flaskTemplate\blueprints\fileController.py", line 59, in download_files
    file_name = record.ids + ".csv"
AttributeError: 'NoneType' object has no attribute 'ids'
2023-04-30 18:07:13,049 | ERROR | 'NoneType' object has no attribute 'ids'
Traceback (most recent call last):
  File "D:\Background\conda\envs\flask365\lib\site-packages\flask\app.py", line 1516, in full_dispatch_request
    rv = self.dispatch_request()
  File "D:\Background\conda\envs\flask365\lib\site-packages\flask\app.py", line 1502, in dispatch_request
    return self.ensure_sync(self.view_functions[rule.endpoint])(**req.view_args)
  File "D:\Project\Money\flaskTemplate\blueprints\fileController.py", line 59, in download_files
    file_name = record.ids + ".csv"
AttributeError: 'NoneType' object has no attribute 'ids'
2023-04-30 18:08:23,081 | ERROR | 'ImmutableMultiDict' object has no attribute 'get_json'
Traceback (most recent call last):
  File "D:\Background\conda\envs\flask365\lib\site-packages\flask\app.py", line 1516, in full_dispatch_request
    rv = self.dispatch_request()
  File "D:\Background\conda\envs\flask365\lib\site-packages\flask\app.py", line 1502, in dispatch_request
    return self.ensure_sync(self.view_functions[rule.endpoint])(**req.view_args)
  File "D:\Project\Money\flaskTemplate\blueprints\fileController.py", line 57, in download_files
    uuid = data.get_json("uuid")
AttributeError: 'ImmutableMultiDict' object has no attribute 'get_json'
2023-05-01 14:18:30,645 | ERROR | invalid literal for int() with base 10: '-0.16104512001161447,-0.16951232550666517,-0.1782793579139222,-0.18666198560349492,-0.19526230046121731,-0.20242409798945732,-0.20890634070899042,-0.21481747809166735,-0.22180369473327885,-0.23162352
Traceback (most recent call last):
  File "D:\Background\conda\envs\flask365\lib\site-packages\flask\app.py", line 1516, in full_dispatch_request
    rv = self.dispatch_request()
  File "D:\Background\conda\envs\flask365\lib\site-packages\flask\app.py", line 1502, in dispatch_request
    return self.ensure_sync(self.view_functions[rule.endpoint])(**req.view_args)
  File "D:\Project\Money\flaskTemplate\blueprints\modelController.py", line 47, in test_model
    generateTestSet(item.addr)
  File "D:\Project\Money\flaskTemplate\torch_model\Test.py", line 66, in generateTestSet
    Y = all_data[:, 0].astype('int32') - 1
ValueError: invalid literal for int() with base 10: '-0.16104512001161447,-0.16951232550666517,-0.1782793579139222,-0.18666198560349492,-0.19526230046121731,-0.20242409798945732,-0.20890634070899042,-0.21481747809166735,-0.22180369473327885,-0.23162352
2023-05-01 14:19:22,657 | ERROR | invalid literal for int() with base 10: '-0.16104512001161447,-0.16951232550666517,-0.1782793579139222,-0.18666198560349492,-0.19526230046121731,-0.20242409798945732,-0.20890634070899042,-0.21481747809166735,-0.22180369473327885,-0.23162352
Traceback (most recent call last):
  File "D:\Background\conda\envs\flask365\lib\site-packages\flask\app.py", line 1516, in full_dispatch_request
    rv = self.dispatch_request()
  File "D:\Background\conda\envs\flask365\lib\site-packages\flask\app.py", line 1502, in dispatch_request
    return self.ensure_sync(self.view_functions[rule.endpoint])(**req.view_args)
  File "D:\Project\Money\flaskTemplate\blueprints\modelController.py", line 47, in test_model
    generateTestSet(item.addr)
  File "D:\Project\Money\flaskTemplate\torch_model\Test.py", line 66, in generateTestSet
    Y = all_data[:, 0].astype('int32') - 1
ValueError: invalid literal for int() with base 10: '-0.16104512001161447,-0.16951232550666517,-0.1782793579139222,-0.18666198560349492,-0.19526230046121731,-0.20242409798945732,-0.20890634070899042,-0.21481747809166735,-0.22180369473327885,-0.23162352
2023-05-01 14:54:14,486 | ERROR | train_size=0 should be either positive and smaller than the number of samples 4107 or a float in the (0, 1) range
Traceback (most recent call last):
  File "D:\Background\conda\envs\flask365\lib\site-packages\flask\app.py", line 1516, in full_dispatch_request
    rv = self.dispatch_request()
  File "D:\Background\conda\envs\flask365\lib\site-packages\flask\app.py", line 1502, in dispatch_request
    return self.ensure_sync(self.view_functions[rule.endpoint])(**req.view_args)
  File "D:\Project\Money\flaskTemplate\blueprints\modelController.py", line 47, in test_model
    generateTestSet(item.addr)
  File "D:\Project\Money\flaskTemplate\torch_model\Test.py", line 75, in generateTestSet
    for train_index, test_index in sss.split(X, Y):
  File "D:\Background\conda\envs\flask365\lib\site-packages\sklearn\model_selection\_split.py", line 1329, in split
    for train, test in self._iter_indices(X, y, groups):
  File "D:\Background\conda\envs\flask365\lib\site-packages\sklearn\model_selection\_split.py", line 1647, in _iter_indices
    default_test_size=self._default_test_size)
  File "D:\Background\conda\envs\flask365\lib\site-packages\sklearn\model_selection\_split.py", line 1763, in _validate_shuffle_split
    '(0, 1) range'.format(train_size, n_samples))
ValueError: train_size=0 should be either positive and smaller than the number of samples 4107 or a float in the (0, 1) range
2023-05-01 15:13:47,586 | ERROR | 'pre_uuid'
Traceback (most recent call last):
  File "D:\Background\conda\envs\flask365\lib\site-packages\flask\app.py", line 1516, in full_dispatch_request
    rv = self.dispatch_request()
  File "D:\Background\conda\envs\flask365\lib\site-packages\flask\app.py", line 1502, in dispatch_request
    return self.ensure_sync(self.view_functions[rule.endpoint])(**req.view_args)
  File "D:\Project\Money\flaskTemplate\blueprints\modelController.py", line 45, in test_model
    pre_uuid = data['pre_uuid']
KeyError: 'pre_uuid'
2023-05-01 15:15:00,239 | ERROR | Dimension out of range (expected to be in range of [-2, 1], but got 2)
Traceback (most recent call last):
  File "D:\Background\conda\envs\flask365\lib\site-packages\flask\app.py", line 1516, in full_dispatch_request
    rv = self.dispatch_request()
  File "D:\Background\conda\envs\flask365\lib\site-packages\flask\app.py", line 1502, in dispatch_request
    return self.ensure_sync(self.view_functions[rule.endpoint])(**req.view_args)
  File "D:\Project\Money\flaskTemplate\blueprints\modelController.py", line 54, in test_model
    evaTest(model_addr, pre_addr)
  File "D:\Project\Money\flaskTemplate\torch_model\Test.py", line 83, in evaTest
    X_test = generateTestSet(set_addr)
  File "D:\Project\Money\flaskTemplate\torch_model\Test.py", line 68, in generateTestSet
    X_test = X_test.transpose(1, 2)
IndexError: Dimension out of range (expected to be in range of [-2, 1], but got 2)
2023-05-01 15:15:24,105 | ERROR | Dimension out of range (expected to be in range of [-2, 1], but got 2)
Traceback (most recent call last):
  File "D:\Background\conda\envs\flask365\lib\site-packages\flask\app.py", line 1516, in full_dispatch_request
    rv = self.dispatch_request()
  File "D:\Background\conda\envs\flask365\lib\site-packages\flask\app.py", line 1502, in dispatch_request
    return self.ensure_sync(self.view_functions[rule.endpoint])(**req.view_args)
  File "D:\Project\Money\flaskTemplate\blueprints\modelController.py", line 54, in test_model
    evaTest(model_addr, pre_addr)
  File "D:\Project\Money\flaskTemplate\torch_model\Test.py", line 83, in evaTest
    X_test = generateTestSet(set_addr)
  File "D:\Project\Money\flaskTemplate\torch_model\Test.py", line 68, in generateTestSet
    X_test = X_test.transpose(1, 2)
IndexError: Dimension out of range (expected to be in range of [-2, 1], but got 2)
2023-05-01 15:15:49,517 | ERROR | Dimension out of range (expected to be in range of [-2, 1], but got 2)
Traceback (most recent call last):
  File "D:\Background\conda\envs\flask365\lib\site-packages\flask\app.py", line 1516, in full_dispatch_request
    rv = self.dispatch_request()
  File "D:\Background\conda\envs\flask365\lib\site-packages\flask\app.py", line 1502, in dispatch_request
    return self.ensure_sync(self.view_functions[rule.endpoint])(**req.view_args)
  File "D:\Project\Money\flaskTemplate\blueprints\modelController.py", line 54, in test_model
    evaTest(model_addr, pre_addr)
  File "D:\Project\Money\flaskTemplate\torch_model\Test.py", line 83, in evaTest
    X_test = generateTestSet(set_addr)
  File "D:\Project\Money\flaskTemplate\torch_model\Test.py", line 68, in generateTestSet
    X_test = X_test.transpose(1, 2)
IndexError: Dimension out of range (expected to be in range of [-2, 1], but got 2)
2023-05-01 15:16:38,675 | ERROR | Dimension out of range (expected to be in range of [-2, 1], but got 2)
Traceback (most recent call last):
  File "D:\Background\conda\envs\flask365\lib\site-packages\flask\app.py", line 1516, in full_dispatch_request
    rv = self.dispatch_request()
  File "D:\Background\conda\envs\flask365\lib\site-packages\flask\app.py", line 1502, in dispatch_request
    return self.ensure_sync(self.view_functions[rule.endpoint])(**req.view_args)
  File "D:\Project\Money\flaskTemplate\blueprints\modelController.py", line 54, in test_model
    evaTest(model_addr, pre_addr)
  File "D:\Project\Money\flaskTemplate\torch_model\Test.py", line 83, in evaTest
    X_test = generateTestSet(set_addr)
  File "D:\Project\Money\flaskTemplate\torch_model\Test.py", line 68, in generateTestSet
    X_test = X_test.transpose(1, 2)
IndexError: Dimension out of range (expected to be in range of [-2, 1], but got 2)
2023-05-01 16:22:52,912 | ERROR | (psycopg2.errors.UndefinedColumn) column "is_completed" of relation "predict" does not exist
LINE 1: ...redict (data_id, model_id, res_addr, create_time, is_complet...
                                                             ^

[SQL: INSERT INTO predict (data_id, model_id, res_addr, create_time, is_completed) VALUES (%(data_id)s, %(model_id)s, %(res_addr)s, %(create_time)s, %(is_completed)s)]
[parameters: {'data_id': '5d4a7805-67fa-4439-b9dd-b9413537b1da', 'model_id': '2515b243-eb4f-4731-b3db-0f9eeae462aa', 'res_addr': 'D:\\Project\\Money\\flaskTemplate\\processed\\472c3e74-ca2d-4736-af08-5173b17672d2.csv', 'create_time': '2023-05-01 16:22:08', 'is_completed': 0}]
(Background on this error at: https://sqlalche.me/e/14/f405)
Traceback (most recent call last):
  File "D:\Background\conda\envs\flask365\lib\site-packages\sqlalchemy\engine\base.py", line 1901, in _execute_context
    cursor, statement, parameters, context
  File "D:\Background\conda\envs\flask365\lib\site-packages\sqlalchemy\engine\default.py", line 736, in do_execute
    cursor.execute(statement, parameters)
psycopg2.errors.UndefinedColumn: column "is_completed" of relation "predict" does not exist
LINE 1: ...redict (data_id, model_id, res_addr, create_time, is_complet...
                                                             ^


The above exception was the direct cause of the following exception:

Traceback (most recent call last):
  File "D:\Background\conda\envs\flask365\lib\site-packages\flask\app.py", line 1516, in full_dispatch_request
    rv = self.dispatch_request()
  File "D:\Background\conda\envs\flask365\lib\site-packages\flask\app.py", line 1502, in dispatch_request
    return self.ensure_sync(self.view_functions[rule.endpoint])(**req.view_args)
  File "D:\Project\Money\flaskTemplate\blueprints\modelController.py", line 67, in test_model
    db.session.commit()
  File "<string>", line 2, in commit
  File "D:\Background\conda\envs\flask365\lib\site-packages\sqlalchemy\orm\session.py", line 1451, in commit
    self._transaction.commit(_to_root=self.future)
  File "D:\Background\conda\envs\flask365\lib\site-packages\sqlalchemy\orm\session.py", line 829, in commit
    self._prepare_impl()
  File "D:\Background\conda\envs\flask365\lib\site-packages\sqlalchemy\orm\session.py", line 808, in _prepare_impl
    self.session.flush()
  File "D:\Background\conda\envs\flask365\lib\site-packages\sqlalchemy\orm\session.py", line 3446, in flush
    self._flush(objects)
  File "D:\Background\conda\envs\flask365\lib\site-packages\sqlalchemy\orm\session.py", line 3586, in _flush
    transaction.rollback(_capture_exception=True)
  File "D:\Background\conda\envs\flask365\lib\site-packages\sqlalchemy\util\langhelpers.py", line 72, in __exit__
    with_traceback=exc_tb,
  File "D:\Background\conda\envs\flask365\lib\site-packages\sqlalchemy\util\compat.py", line 211, in raise_
    raise exception
  File "D:\Background\conda\envs\flask365\lib\site-packages\sqlalchemy\orm\session.py", line 3546, in _flush
    flush_context.execute()
  File "D:\Background\conda\envs\flask365\lib\site-packages\sqlalchemy\orm\unitofwork.py", line 456, in execute
    rec.execute(self)
  File "D:\Background\conda\envs\flask365\lib\site-packages\sqlalchemy\orm\unitofwork.py", line 633, in execute
    uow,
  File "D:\Background\conda\envs\flask365\lib\site-packages\sqlalchemy\orm\persistence.py", line 250, in save_obj
    insert,
  File "D:\Background\conda\envs\flask365\lib\site-packages\sqlalchemy\orm\persistence.py", line 1098, in _emit_insert_statements
    statement, multiparams, execution_options=execution_options
  File "D:\Background\conda\envs\flask365\lib\site-packages\sqlalchemy\engine\base.py", line 1705, in _execute_20
    return meth(self, args_10style, kwargs_10style, execution_options)
  File "D:\Background\conda\envs\flask365\lib\site-packages\sqlalchemy\sql\elements.py", line 335, in _execute_on_connection
    self, multiparams, params, execution_options
  File "D:\Background\conda\envs\flask365\lib\site-packages\sqlalchemy\engine\base.py", line 1582, in _execute_clauseelement
    cache_hit=cache_hit,
  File "D:\Background\conda\envs\flask365\lib\site-packages\sqlalchemy\engine\base.py", line 1944, in _execute_context
    e, statement, parameters, cursor, context
  File "D:\Background\conda\envs\flask365\lib\site-packages\sqlalchemy\engine\base.py", line 2125, in _handle_dbapi_exception
    sqlalchemy_exception, with_traceback=exc_info[2], from_=e
  File "D:\Background\conda\envs\flask365\lib\site-packages\sqlalchemy\util\compat.py", line 211, in raise_
    raise exception
  File "D:\Background\conda\envs\flask365\lib\site-packages\sqlalchemy\engine\base.py", line 1901, in _execute_context
    cursor, statement, parameters, context
  File "D:\Background\conda\envs\flask365\lib\site-packages\sqlalchemy\engine\default.py", line 736, in do_execute
    cursor.execute(statement, parameters)
sqlalchemy.exc.ProgrammingError: (psycopg2.errors.UndefinedColumn) column "is_completed" of relation "predict" does not exist
LINE 1: ...redict (data_id, model_id, res_addr, create_time, is_complet...
                                                             ^

[SQL: INSERT INTO predict (data_id, model_id, res_addr, create_time, is_completed) VALUES (%(data_id)s, %(model_id)s, %(res_addr)s, %(create_time)s, %(is_completed)s)]
[parameters: {'data_id': '5d4a7805-67fa-4439-b9dd-b9413537b1da', 'model_id': '2515b243-eb4f-4731-b3db-0f9eeae462aa', 'res_addr': 'D:\\Project\\Money\\flaskTemplate\\processed\\472c3e74-ca2d-4736-af08-5173b17672d2.csv', 'create_time': '2023-05-01 16:22:08', 'is_completed': 0}]
(Background on this error at: https://sqlalche.me/e/14/f405)
2023-05-01 22:11:40,804 | ERROR | 'list' object has no attribute 'paginate'
Traceback (most recent call last):
  File "D:\Background\conda\envs\flask365\lib\site-packages\flask\app.py", line 1516, in full_dispatch_request
    rv = self.dispatch_request()
  File "D:\Background\conda\envs\flask365\lib\site-packages\flask\app.py", line 1502, in dispatch_request
    return self.ensure_sync(self.view_functions[rule.endpoint])(**req.view_args)
  File "D:\Project\Money\flaskTemplate\blueprints\fileController.py", line 73, in get_progress
    records = Record.query.all().paginate(page=page, per_page=page_size)
AttributeError: 'list' object has no attribute 'paginate'
2023-05-01 22:25:02,106 | ERROR | Only '=', '!=', 'is_()', 'is_not()', 'is_distinct_from()', 'is_not_distinct_from()' operators can be used with None/True/False
Traceback (most recent call last):
  File "D:\Background\conda\envs\flask365\lib\site-packages\flask\app.py", line 1516, in full_dispatch_request
    rv = self.dispatch_request()
  File "D:\Background\conda\envs\flask365\lib\site-packages\flask\app.py", line 1502, in dispatch_request
    return self.ensure_sync(self.view_functions[rule.endpoint])(**req.view_args)
  File "D:\Project\Money\flaskTemplate\blueprints\fileController.py", line 118, in queryRecordByID
    records = Record.query.filter(Record.ids.like(record_id)).paginate(page=page, per_page=page_size)
  File "D:\Background\conda\envs\flask365\lib\site-packages\sqlalchemy\sql\operators.py", line 523, in like
    return self.operate(like_op, other, escape=escape)
  File "D:\Background\conda\envs\flask365\lib\site-packages\sqlalchemy\orm\attributes.py", line 317, in operate
    return op(self.comparator, *other, **kwargs)
  File "D:\Background\conda\envs\flask365\lib\site-packages\sqlalchemy\sql\operators.py", line 1381, in like_op
    return a.like(b, escape=escape)
  File "D:\Background\conda\envs\flask365\lib\site-packages\sqlalchemy\sql\operators.py", line 523, in like
    return self.operate(like_op, other, escape=escape)
  File "D:\Background\conda\envs\flask365\lib\site-packages\sqlalchemy\orm\properties.py", line 426, in operate
    return op(self.__clause_element__(), *other, **kwargs)
  File "D:\Background\conda\envs\flask365\lib\site-packages\sqlalchemy\sql\operators.py", line 1381, in like_op
    return a.like(b, escape=escape)
  File "D:\Background\conda\envs\flask365\lib\site-packages\sqlalchemy\sql\operators.py", line 523, in like
    return self.operate(like_op, other, escape=escape)
  File "D:\Background\conda\envs\flask365\lib\site-packages\sqlalchemy\sql\elements.py", line 870, in operate
    return op(self.comparator, *other, **kwargs)
  File "D:\Background\conda\envs\flask365\lib\site-packages\sqlalchemy\sql\operators.py", line 1381, in like_op
    return a.like(b, escape=escape)
  File "D:\Background\conda\envs\flask365\lib\site-packages\sqlalchemy\sql\operators.py", line 523, in like
    return self.operate(like_op, other, escape=escape)
  File "D:\Background\conda\envs\flask365\lib\site-packages\sqlalchemy\sql\type_api.py", line 77, in operate
    return o[0](self.expr, op, *(other + o[1:]), **kwargs)
  File "D:\Background\conda\envs\flask365\lib\site-packages\sqlalchemy\sql\default_comparator.py", line 96, in _boolean_compare
    "Only '=', '!=', 'is_()', 'is_not()', "
sqlalchemy.exc.ArgumentError: Only '=', '!=', 'is_()', 'is_not()', 'is_distinct_from()', 'is_not_distinct_from()' operators can be used with None/True/False
2023-05-01 22:25:35,554 | ERROR | Only '=', '!=', 'is_()', 'is_not()', 'is_distinct_from()', 'is_not_distinct_from()' operators can be used with None/True/False
Traceback (most recent call last):
  File "D:\Background\conda\envs\flask365\lib\site-packages\flask\app.py", line 1516, in full_dispatch_request
    rv = self.dispatch_request()
  File "D:\Background\conda\envs\flask365\lib\site-packages\flask\app.py", line 1502, in dispatch_request
    return self.ensure_sync(self.view_functions[rule.endpoint])(**req.view_args)
  File "D:\Project\Money\flaskTemplate\blueprints\fileController.py", line 118, in queryRecordByID
    records = Record.query.filter(Record.ids.like(record_id)).paginate(page=page, per_page=page_size)
  File "D:\Background\conda\envs\flask365\lib\site-packages\sqlalchemy\sql\operators.py", line 523, in like
    return self.operate(like_op, other, escape=escape)
  File "D:\Background\conda\envs\flask365\lib\site-packages\sqlalchemy\orm\attributes.py", line 317, in operate
    return op(self.comparator, *other, **kwargs)
  File "D:\Background\conda\envs\flask365\lib\site-packages\sqlalchemy\sql\operators.py", line 1381, in like_op
    return a.like(b, escape=escape)
  File "D:\Background\conda\envs\flask365\lib\site-packages\sqlalchemy\sql\operators.py", line 523, in like
    return self.operate(like_op, other, escape=escape)
  File "D:\Background\conda\envs\flask365\lib\site-packages\sqlalchemy\orm\properties.py", line 426, in operate
    return op(self.__clause_element__(), *other, **kwargs)
  File "D:\Background\conda\envs\flask365\lib\site-packages\sqlalchemy\sql\operators.py", line 1381, in like_op
    return a.like(b, escape=escape)
  File "D:\Background\conda\envs\flask365\lib\site-packages\sqlalchemy\sql\operators.py", line 523, in like
    return self.operate(like_op, other, escape=escape)
  File "D:\Background\conda\envs\flask365\lib\site-packages\sqlalchemy\sql\elements.py", line 870, in operate
    return op(self.comparator, *other, **kwargs)
  File "D:\Background\conda\envs\flask365\lib\site-packages\sqlalchemy\sql\operators.py", line 1381, in like_op
    return a.like(b, escape=escape)
  File "D:\Background\conda\envs\flask365\lib\site-packages\sqlalchemy\sql\operators.py", line 523, in like
    return self.operate(like_op, other, escape=escape)
  File "D:\Background\conda\envs\flask365\lib\site-packages\sqlalchemy\sql\type_api.py", line 77, in operate
    return o[0](self.expr, op, *(other + o[1:]), **kwargs)
  File "D:\Background\conda\envs\flask365\lib\site-packages\sqlalchemy\sql\default_comparator.py", line 96, in _boolean_compare
    "Only '=', '!=', 'is_()', 'is_not()', "
sqlalchemy.exc.ArgumentError: Only '=', '!=', 'is_()', 'is_not()', 'is_distinct_from()', 'is_not_distinct_from()' operators can be used with None/True/False
2023-05-01 22:25:41,411 | ERROR | Only '=', '!=', 'is_()', 'is_not()', 'is_distinct_from()', 'is_not_distinct_from()' operators can be used with None/True/False
Traceback (most recent call last):
  File "D:\Background\conda\envs\flask365\lib\site-packages\flask\app.py", line 1516, in full_dispatch_request
    rv = self.dispatch_request()
  File "D:\Background\conda\envs\flask365\lib\site-packages\flask\app.py", line 1502, in dispatch_request
    return self.ensure_sync(self.view_functions[rule.endpoint])(**req.view_args)
  File "D:\Project\Money\flaskTemplate\blueprints\fileController.py", line 118, in queryRecordByID
    records = Record.query.filter(Record.ids.like(record_id)).paginate(page=page, per_page=page_size)
  File "D:\Background\conda\envs\flask365\lib\site-packages\sqlalchemy\sql\operators.py", line 523, in like
    return self.operate(like_op, other, escape=escape)
  File "D:\Background\conda\envs\flask365\lib\site-packages\sqlalchemy\orm\attributes.py", line 317, in operate
    return op(self.comparator, *other, **kwargs)
  File "D:\Background\conda\envs\flask365\lib\site-packages\sqlalchemy\sql\operators.py", line 1381, in like_op
    return a.like(b, escape=escape)
  File "D:\Background\conda\envs\flask365\lib\site-packages\sqlalchemy\sql\operators.py", line 523, in like
    return self.operate(like_op, other, escape=escape)
  File "D:\Background\conda\envs\flask365\lib\site-packages\sqlalchemy\orm\properties.py", line 426, in operate
    return op(self.__clause_element__(), *other, **kwargs)
  File "D:\Background\conda\envs\flask365\lib\site-packages\sqlalchemy\sql\operators.py", line 1381, in like_op
    return a.like(b, escape=escape)
  File "D:\Background\conda\envs\flask365\lib\site-packages\sqlalchemy\sql\operators.py", line 523, in like
    return self.operate(like_op, other, escape=escape)
  File "D:\Background\conda\envs\flask365\lib\site-packages\sqlalchemy\sql\elements.py", line 870, in operate
    return op(self.comparator, *other, **kwargs)
  File "D:\Background\conda\envs\flask365\lib\site-packages\sqlalchemy\sql\operators.py", line 1381, in like_op
    return a.like(b, escape=escape)
  File "D:\Background\conda\envs\flask365\lib\site-packages\sqlalchemy\sql\operators.py", line 523, in like
    return self.operate(like_op, other, escape=escape)
  File "D:\Background\conda\envs\flask365\lib\site-packages\sqlalchemy\sql\type_api.py", line 77, in operate
    return o[0](self.expr, op, *(other + o[1:]), **kwargs)
  File "D:\Background\conda\envs\flask365\lib\site-packages\sqlalchemy\sql\default_comparator.py", line 96, in _boolean_compare
    "Only '=', '!=', 'is_()', 'is_not()', "
sqlalchemy.exc.ArgumentError: Only '=', '!=', 'is_()', 'is_not()', 'is_distinct_from()', 'is_not_distinct_from()' operators can be used with None/True/False
2023-05-01 22:26:39,276 | ERROR | must be str, not NoneType
Traceback (most recent call last):
  File "D:\Background\conda\envs\flask365\lib\site-packages\flask\app.py", line 1516, in full_dispatch_request
    rv = self.dispatch_request()
  File "D:\Background\conda\envs\flask365\lib\site-packages\flask\app.py", line 1502, in dispatch_request
    return self.ensure_sync(self.view_functions[rule.endpoint])(**req.view_args)
  File "D:\Project\Money\flaskTemplate\blueprints\fileController.py", line 118, in queryRecordByID
    records = Record.query.filter(Record.ids.like('%'+record_id+"%")).paginate(page=page, per_page=page_size)
TypeError: must be str, not NoneType
2023-05-01 23:41:53,413 | ERROR | 'NoneType' object is not iterable
Traceback (most recent call last):
  File "D:\Background\conda\envs\flask365\lib\site-packages\flask\app.py", line 1516, in full_dispatch_request
    rv = self.dispatch_request()
  File "D:\Background\conda\envs\flask365\lib\site-packages\flask\app.py", line 1502, in dispatch_request
    return self.ensure_sync(self.view_functions[rule.endpoint])(**req.view_args)
  File "D:\Project\Money\flaskTemplate\blueprints\fileController.py", line 61, in chose_file
    ids = '-'.join([str(elem) for elem in chose])
TypeError: 'NoneType' object is not iterable
2023-05-01 23:42:28,349 | ERROR | 'NoneType' object is not iterable
Traceback (most recent call last):
  File "D:\Background\conda\envs\flask365\lib\site-packages\flask\app.py", line 1516, in full_dispatch_request
    rv = self.dispatch_request()
  File "D:\Background\conda\envs\flask365\lib\site-packages\flask\app.py", line 1502, in dispatch_request
    return self.ensure_sync(self.view_functions[rule.endpoint])(**req.view_args)
  File "D:\Project\Money\flaskTemplate\blueprints\fileController.py", line 61, in chose_file
    ids = '-'.join([str(elem) for elem in chose])
TypeError: 'NoneType' object is not iterable
2023-05-01 23:51:32,303 | ERROR | 'BaseQuery' object has no attribute 'id'
Traceback (most recent call last):
  File "D:\Background\conda\envs\flask365\lib\site-packages\flask\app.py", line 1516, in full_dispatch_request
    rv = self.dispatch_request()
  File "D:\Background\conda\envs\flask365\lib\site-packages\flask\app.py", line 1502, in dispatch_request
    return self.ensure_sync(self.view_functions[rule.endpoint])(**req.view_args)
  File "D:\Project\Money\flaskTemplate\blueprints\fileController.py", line 108, in queryRecordByUUID
    "uuid": item.id,
AttributeError: 'BaseQuery' object has no attribute 'id'
2023-05-01 23:52:38,348 | ERROR | 'BaseQuery' object has no attribute 'id'
Traceback (most recent call last):
  File "D:\Background\conda\envs\flask365\lib\site-packages\flask\app.py", line 1516, in full_dispatch_request
    rv = self.dispatch_request()
  File "D:\Background\conda\envs\flask365\lib\site-packages\flask\app.py", line 1502, in dispatch_request
    return self.ensure_sync(self.view_functions[rule.endpoint])(**req.view_args)
  File "D:\Project\Money\flaskTemplate\blueprints\fileController.py", line 108, in queryRecordByUUID
    "uuid": item.id,
AttributeError: 'BaseQuery' object has no attribute 'id'
2023-05-01 23:59:47,718 | ERROR | 'BaseQuery' object has no attribute 'query'
Traceback (most recent call last):
  File "D:\Background\conda\envs\flask365\lib\site-packages\flask\app.py", line 1516, in full_dispatch_request
    rv = self.dispatch_request()
  File "D:\Background\conda\envs\flask365\lib\site-packages\flask\app.py", line 1502, in dispatch_request
    return self.ensure_sync(self.view_functions[rule.endpoint])(**req.view_args)
  File "D:\Project\Money\flaskTemplate\blueprints\modelController.py", line 111, in getAllTestRecords
    pres = Predict.query.query.paginate(page=page, per_page=page_size)
AttributeError: 'BaseQuery' object has no attribute 'query'
